[2024-02-02 19:18:09,501 : INFO: main :Custsome log]
[2024-02-24 16:16:15,285 : INFO: main :Starting data ingestion pipeline]
[2024-02-24 16:16:58,800 : INFO: main :Starting data ingestion pipeline]
[2024-02-24 16:18:47,404 : INFO: main :Starting data ingestion pipeline]
[2024-02-24 16:20:47,261 : INFO: main :Starting data ingestion pipeline]
[2024-02-24 16:20:47,263 : INFO: common :yaml file: config/config.yaml loaded successfully]
[2024-02-24 16:20:47,264 : INFO: common :yaml file: params.yaml loaded successfully]
[2024-02-24 16:21:26,051 : INFO: main :Starting data ingestion pipeline]
[2024-02-24 16:21:26,053 : INFO: common :yaml file: config/config.yaml loaded successfully]
[2024-02-24 16:21:26,053 : INFO: common :yaml file: params.yaml loaded successfully]
[2024-02-24 16:22:33,573 : INFO: main :Starting data ingestion pipeline]
[2024-02-24 16:22:33,574 : INFO: common :yaml file: config/config.yaml loaded successfully]
[2024-02-24 16:22:33,575 : INFO: common :yaml file: params.yaml loaded successfully]
[2024-02-24 16:27:14,907 : INFO: main :Starting data ingestion pipeline]
[2024-02-24 16:30:59,022 : INFO: main :Starting data ingestion pipeline]
[2024-02-24 16:30:59,023 : INFO: common :yaml file: config/config.yaml loaded successfully]
[2024-02-24 16:30:59,024 : INFO: common :yaml file: params.yaml loaded successfully]
[2024-02-24 16:32:59,829 : INFO: main :Starting data ingestion pipeline]
[2024-02-24 16:32:59,831 : INFO: common :yaml file: config/config.yaml loaded successfully]
[2024-02-24 16:32:59,831 : INFO: common :yaml file: params.yaml loaded successfully]
[2024-02-29 18:14:03,678 : INFO: common :yaml file: config/config.yaml loaded successfully]
[2024-02-29 18:14:03,679 : INFO: common :yaml file: params.yaml loaded successfully]
[2024-02-29 18:14:03,680 : INFO: common :created directory at: artifats]
[2024-02-29 18:14:03,680 : INFO: common :created directory at: artifacts/data_ingestion]
[2024-02-29 18:15:53,586 : INFO: common :yaml file: config/config.yaml loaded successfully]
[2024-02-29 18:15:53,587 : INFO: common :yaml file: params.yaml loaded successfully]
[2024-02-29 18:15:53,587 : INFO: common :created directory at: artifats]
[2024-02-29 18:15:53,587 : INFO: common :created directory at: artifacts/data_ingestion]
[2024-02-29 18:15:55,815 : INFO: data_ingestion :artifacts/data_ingestion/data.zip download! with following info: 
Content-Type: text/html; charset=utf-8
X-Robots-Tag: noindex, nofollow, nosnippet
Cache-Control: no-cache, no-store, max-age=0, must-revalidate
Pragma: no-cache
Expires: Mon, 01 Jan 1990 00:00:00 GMT
Date: Thu, 29 Feb 2024 12:45:55 GMT
P3P: CP="This is not a P3P policy! See g.co/p3phelp for more info."
Content-Security-Policy: require-trusted-types-for 'script';report-uri https://csp.withgoogle.com/csp/docs-tt
Referrer-Policy: origin
X-Content-Type-Options: nosniff
X-Frame-Options: SAMEORIGIN
X-XSS-Protection: 1; mode=block
Server: GSE
Set-Cookie: NID=512=T7jeraYNAPiXPGL3x6cZ4RgYJXWVEDalUQ6DFwQUb8vKBwzqsfqXhosXjYdDCnkiTXEMWZB4LjLxc7aC2tpXkrO7MvpxbbMVOEq1Roffo8qxT70HFZXbY7lhQETbRvd2EgqTdiq5MsqnjigEeCWb_Jh1TPMnfMJXJgAFiDJU4tw; expires=Fri, 30-Aug-2024 12:45:54 GMT; path=/; domain=.google.com; HttpOnly
Alt-Svc: h3=":443"; ma=2592000,h3-29=":443"; ma=2592000
Accept-Ranges: none
Vary: Sec-Fetch-Dest, Sec-Fetch-Mode, Sec-Fetch-Site,Accept-Encoding
Connection: close
Transfer-Encoding: chunked

]
[2024-02-29 18:19:25,569 : INFO: common :yaml file: config/config.yaml loaded successfully]
[2024-02-29 18:19:25,569 : INFO: common :yaml file: params.yaml loaded successfully]
[2024-02-29 18:19:25,570 : INFO: common :created directory at: artifats]
[2024-02-29 18:19:25,570 : INFO: common :created directory at: artifacts/data_ingestion]
[2024-02-29 18:19:27,156 : INFO: data_ingestion :artifacts/data_ingestion/data.zip download! with following info: 
Content-Type: text/html; charset=utf-8
X-Robots-Tag: noindex, nofollow, nosnippet
Cache-Control: no-cache, no-store, max-age=0, must-revalidate
Pragma: no-cache
Expires: Mon, 01 Jan 1990 00:00:00 GMT
Date: Thu, 29 Feb 2024 12:49:26 GMT
P3P: CP="This is not a P3P policy! See g.co/p3phelp for more info."
Content-Security-Policy: require-trusted-types-for 'script';report-uri https://csp.withgoogle.com/csp/docs-tt
Referrer-Policy: origin
X-Content-Type-Options: nosniff
X-Frame-Options: SAMEORIGIN
X-XSS-Protection: 1; mode=block
Server: GSE
Set-Cookie: NID=512=MZWw5jNz0e9f-Rr2HZ4g5hCY42gllVX8O2LaFBbZl04nvDQp6V1PcoZz9NYp65jQyBPw_UCgU0U_gnkYrshmKT7jNlatEVmT8cOr_3L1pxWG04LNjisgWTLPu75K0HkMsK7lbVd7uuQSQ_AQypo9UTuqmFHJ5zjAJ-SNXoQr6xg; expires=Fri, 30-Aug-2024 12:49:26 GMT; path=/; domain=.google.com; HttpOnly
Alt-Svc: h3=":443"; ma=2592000,h3-29=":443"; ma=2592000
Accept-Ranges: none
Vary: Sec-Fetch-Dest, Sec-Fetch-Mode, Sec-Fetch-Site,Accept-Encoding
Connection: close
Transfer-Encoding: chunked

]
[2024-02-29 18:30:19,258 : INFO: common :yaml file: config/config.yaml loaded successfully]
[2024-02-29 18:30:19,259 : INFO: common :yaml file: params.yaml loaded successfully]
[2024-02-29 18:30:19,259 : INFO: common :created directory at: artifats]
[2024-02-29 18:30:19,259 : INFO: common :created directory at: artifacts/data_ingestion]
[2024-02-29 18:30:20,944 : INFO: data_ingestion :artifacts/data_ingestion/data.zip download! with following info: 
Content-Type: text/html; charset=utf-8
X-Robots-Tag: noindex, nofollow, nosnippet
Cache-Control: no-cache, no-store, max-age=0, must-revalidate
Pragma: no-cache
Expires: Mon, 01 Jan 1990 00:00:00 GMT
Date: Thu, 29 Feb 2024 13:00:20 GMT
P3P: CP="This is not a P3P policy! See g.co/p3phelp for more info."
Content-Security-Policy: require-trusted-types-for 'script';report-uri https://csp.withgoogle.com/csp/docs-tt
Referrer-Policy: origin
X-Content-Type-Options: nosniff
X-Frame-Options: SAMEORIGIN
X-XSS-Protection: 1; mode=block
Server: GSE
Set-Cookie: NID=512=cdb5XN-kyg_arkm4nDTz9GnQhMAnS33goiBTs1ojl6l-PDAT9hwMCqU0e_uJ-p8VUX4WDz7CKh7F6EV5Ll-ApKNYea2BgyyaV6_HUD6Ivq7xDFSzco_BqddM4mlABg3Q7cIbpSoUb_ShtwklbjpwdHnGloF5zSMQc7bfJJsDct4; expires=Fri, 30-Aug-2024 13:00:20 GMT; path=/; domain=.google.com; HttpOnly
Alt-Svc: h3=":443"; ma=2592000,h3-29=":443"; ma=2592000
Accept-Ranges: none
Vary: Sec-Fetch-Dest, Sec-Fetch-Mode, Sec-Fetch-Site,Accept-Encoding
Connection: close
Transfer-Encoding: chunked

]
[2024-02-29 18:35:45,068 : INFO: common :yaml file: config/config.yaml loaded successfully]
[2024-02-29 18:35:45,069 : INFO: common :yaml file: params.yaml loaded successfully]
[2024-02-29 18:35:45,069 : INFO: common :created directory at: artifats]
[2024-02-29 18:35:45,069 : INFO: common :created directory at: artifacts/data_ingestion]
[2024-02-29 18:37:01,128 : INFO: common :yaml file: config/config.yaml loaded successfully]
[2024-02-29 18:37:01,129 : INFO: common :yaml file: params.yaml loaded successfully]
[2024-02-29 18:37:01,129 : INFO: common :created directory at: artifacts]
[2024-02-29 18:37:01,129 : INFO: common :created directory at: artifacts/data_ingestion]
[2024-02-29 18:37:02,453 : INFO: data_ingestion :artifacts/data_ingestion/data.zip download! with following info: 
Content-Type: text/html; charset=utf-8
X-Robots-Tag: noindex, nofollow, nosnippet
Cache-Control: no-cache, no-store, max-age=0, must-revalidate
Pragma: no-cache
Expires: Mon, 01 Jan 1990 00:00:00 GMT
Date: Thu, 29 Feb 2024 13:07:02 GMT
P3P: CP="This is not a P3P policy! See g.co/p3phelp for more info."
Content-Security-Policy: require-trusted-types-for 'script';report-uri https://csp.withgoogle.com/csp/docs-tt
Referrer-Policy: origin
X-Content-Type-Options: nosniff
X-Frame-Options: SAMEORIGIN
X-XSS-Protection: 1; mode=block
Server: GSE
Set-Cookie: NID=512=p7eLzIamyU96hMRMMFvryD63IePfBvnwnOCcQEMG_kUvO-Atu2cWAl52cP0Otg7SxR672T6YKIJ0rB3M28WG995b-xf2mjH2J3uiETRFJXiToXnFr3fbq-WJIUzbUV9BS8QpwQxUW_Kmz3QgZYhgkYxaP40tkOeNEUcUYKRTbeU; expires=Fri, 30-Aug-2024 13:07:01 GMT; path=/; domain=.google.com; HttpOnly
Alt-Svc: h3=":443"; ma=2592000,h3-29=":443"; ma=2592000
Accept-Ranges: none
Vary: Sec-Fetch-Dest, Sec-Fetch-Mode, Sec-Fetch-Site,Accept-Encoding
Connection: close
Transfer-Encoding: chunked

]
[2024-02-29 18:39:53,699 : INFO: common :yaml file: config/config.yaml loaded successfully]
[2024-02-29 18:39:53,699 : INFO: common :yaml file: params.yaml loaded successfully]
[2024-02-29 18:39:53,700 : INFO: common :created directory at: artifacts]
[2024-02-29 18:39:53,700 : INFO: common :created directory at: artifacts/data_ingestion]
[2024-02-29 18:44:13,147 : INFO: common :yaml file: config/config.yaml loaded successfully]
[2024-02-29 18:44:13,148 : INFO: common :yaml file: params.yaml loaded successfully]
[2024-02-29 18:44:13,148 : INFO: common :created directory at: artifacts]
[2024-02-29 18:44:13,149 : INFO: common :created directory at: artifacts/data_ingestion]
[2024-02-29 18:47:23,856 : INFO: main :Starting data ingestion pipeline]
[2024-03-08 16:14:47,193 : INFO: common :yaml file: config/config.yaml loaded successfully]
[2024-03-08 16:14:47,195 : INFO: common :yaml file: params.yaml loaded successfully]
[2024-03-08 16:14:47,195 : INFO: common :created directory at: artifacts]
[2024-03-08 16:16:01,496 : INFO: common :yaml file: config/config.yaml loaded successfully]
[2024-03-08 16:16:01,497 : INFO: common :yaml file: params.yaml loaded successfully]
[2024-03-08 16:16:01,498 : INFO: common :created directory at: artifacts]
[2024-03-08 16:16:01,498 : INFO: common :created directory at: artifacts/base_model]
[2024-03-08 16:17:46,170 : INFO: common :yaml file: config/config.yaml loaded successfully]
[2024-03-08 16:17:46,171 : INFO: common :yaml file: params.yaml loaded successfully]
[2024-03-08 16:17:46,171 : INFO: common :created directory at: artifacts]
[2024-03-08 16:17:46,171 : INFO: common :created directory at: artifacts/base_model]
[2024-03-08 16:20:24,442 : INFO: common :yaml file: config/config.yaml loaded successfully]
[2024-03-08 16:20:24,443 : INFO: common :yaml file: params.yaml loaded successfully]
[2024-03-08 16:20:24,443 : INFO: common :created directory at: artifacts]
[2024-03-08 16:20:24,443 : INFO: common :created directory at: artifacts/prepare_base_model]
[2024-03-08 16:23:38,487 : INFO: common :yaml file: config/config.yaml loaded successfully]
[2024-03-08 16:23:38,488 : INFO: common :yaml file: params.yaml loaded successfully]
[2024-03-08 16:23:38,488 : INFO: common :created directory at: artifacts]
[2024-03-08 16:23:38,488 : INFO: common :created directory at: artifacts/prepare_base_model]
[2024-03-08 16:29:37,244 : INFO: common :yaml file: config/config.yaml loaded successfully]
[2024-03-08 16:29:37,245 : INFO: common :yaml file: params.yaml loaded successfully]
[2024-03-08 16:29:37,245 : INFO: common :created directory at: artifacts]
[2024-03-08 16:29:37,245 : INFO: common :created directory at: artifacts/prepare_base_model]
[2024-03-08 16:33:07,691 : INFO: main :*******************]
[2024-03-08 16:33:07,691 : ERROR: main :name 'STAGE_NAME' is not defined]
Traceback (most recent call last):
  File "main.py", line 17, in <module>
    logger.info(f">>>>>> stage {STAGE_NAME} started <<<<<<")
NameError: name 'STAGE_NAME' is not defined
[2024-03-08 16:33:46,006 : INFO: main :*******************]
[2024-03-08 16:33:46,006 : INFO: main :>>>>>> stage Prepare base model started <<<<<<]
[2024-03-08 16:33:46,008 : INFO: common :yaml file: config/config.yaml loaded successfully]
[2024-03-08 16:33:46,009 : INFO: common :yaml file: params.yaml loaded successfully]
[2024-03-08 16:33:46,009 : INFO: common :created directory at: artifacts]
[2024-03-08 16:33:46,009 : INFO: common :created directory at: artifacts/prepare_base_model]
[2024-03-08 16:37:10,055 : WARNING: saving_utils :Compiled the loaded model, but the compiled metrics have yet to be built. `model.compile_metrics` will be empty until you train or evaluate the model.]
[2024-03-08 16:37:10,271 : INFO: main :>>>>>> stage Prepare base model completed <<<<<<

x==========x]
[2024-03-10 15:19:03,674 : INFO: main :*******************]
[2024-03-10 15:19:03,675 : INFO: main :>>>>>> stage Training Phase started <<<<<<]
[2024-03-10 15:19:03,678 : INFO: common :yaml file: config/config.yaml loaded successfully]
[2024-03-10 15:19:03,680 : INFO: common :yaml file: params.yaml loaded successfully]
[2024-03-10 15:19:03,680 : INFO: common :created directory at: artifacts]
[2024-03-10 15:19:03,680 : ERROR: main :Argument path_to_directories of type <class 'pathlib.PosixPath'> to <function create_directories at 0x7f05638bd700> does not match annotation type <class 'list'>]
Traceback (most recent call last):
  File "main.py", line 31, in <module>
    obj.main()
  File "/home/sumedh/Documents/MLops_tutorial/Project_2/Kidney_disease_classification/src/cnn_classifier/pipeline/s3_model_training.py", line 21, in main
    raise e
  File "/home/sumedh/Documents/MLops_tutorial/Project_2/Kidney_disease_classification/src/cnn_classifier/pipeline/s3_model_training.py", line 14, in main
    training_config = config.get_training_config()
  File "/home/sumedh/Documents/MLops_tutorial/Project_2/Kidney_disease_classification/src/cnn_classifier/config/configuration.py", line 61, in get_training_config
    create_directories(
  File "/home/sumedh/anaconda3/envs/classification/lib/python3.8/site-packages/ensure/main.py", line 803, in __call__
    raise EnsureError(msg.format(
ensure.main.EnsureError: Argument path_to_directories of type <class 'pathlib.PosixPath'> to <function create_directories at 0x7f05638bd700> does not match annotation type <class 'list'>
[2024-03-10 15:21:10,920 : INFO: main :*******************]
[2024-03-10 15:21:10,920 : INFO: main :>>>>>> stage Training Phase started <<<<<<]
[2024-03-10 15:21:10,923 : INFO: common :yaml file: config/config.yaml loaded successfully]
[2024-03-10 15:21:10,924 : INFO: common :yaml file: params.yaml loaded successfully]
[2024-03-10 15:21:10,924 : INFO: common :created directory at: artifacts]
[2024-03-10 15:21:10,925 : INFO: common :created directory at: artifacts/training]
[2024-03-10 15:21:10,925 : ERROR: main :"'ConfigBox' object has no attribute 'training_data'"]
Traceback (most recent call last):
  File "box/box.py", line 503, in box.box.Box.__getitem__
KeyError: 'training_data'

The above exception was the direct cause of the following exception:

Traceback (most recent call last):
  File "box/box.py", line 536, in box.box.Box.__getattr__
  File "box/box.py", line 524, in box.box.Box.__getitem__
box.exceptions.BoxKeyError: "'training_data'"

During handling of the above exception, another exception occurred:

Traceback (most recent call last):
  File "box/box.py", line 538, in box.box.Box.__getattr__
AttributeError: 'ConfigBox' object has no attribute 'training_data'

The above exception was the direct cause of the following exception:

Traceback (most recent call last):
  File "box/config_box.py", line 28, in box.config_box.ConfigBox.__getattr__
  File "box/box.py", line 552, in box.box.Box.__getattr__
box.exceptions.BoxKeyError: "'ConfigBox' object has no attribute 'training_data'"

During handling of the above exception, another exception occurred:

Traceback (most recent call last):
  File "box/box.py", line 503, in box.box.Box.__getitem__
KeyError: 'training_data'

The above exception was the direct cause of the following exception:

Traceback (most recent call last):
  File "box/box.py", line 536, in box.box.Box.__getattr__
  File "box/box.py", line 524, in box.box.Box.__getitem__
box.exceptions.BoxKeyError: "'training_data'"

During handling of the above exception, another exception occurred:

Traceback (most recent call last):
  File "box/box.py", line 538, in box.box.Box.__getattr__
AttributeError: 'ConfigBox' object has no attribute 'training_data'

The above exception was the direct cause of the following exception:

Traceback (most recent call last):
  File "main.py", line 31, in <module>
    obj.main()
  File "/home/sumedh/Documents/MLops_tutorial/Project_2/Kidney_disease_classification/src/cnn_classifier/pipeline/s3_model_training.py", line 21, in main
    raise e
  File "/home/sumedh/Documents/MLops_tutorial/Project_2/Kidney_disease_classification/src/cnn_classifier/pipeline/s3_model_training.py", line 14, in main
    training_config = config.get_training_config()
  File "/home/sumedh/Documents/MLops_tutorial/Project_2/Kidney_disease_classification/src/cnn_classifier/config/configuration.py", line 69, in get_training_config
    training_data= Path(training.training_data),
  File "box/config_box.py", line 30, in box.config_box.ConfigBox.__getattr__
  File "box/box.py", line 552, in box.box.Box.__getattr__
box.exceptions.BoxKeyError: "'ConfigBox' object has no attribute 'training_data'"
[2024-03-10 15:23:18,351 : INFO: main :*******************]
[2024-03-10 15:23:18,351 : INFO: main :>>>>>> stage Training Phase started <<<<<<]
[2024-03-10 15:23:18,354 : INFO: common :yaml file: config/config.yaml loaded successfully]
[2024-03-10 15:23:18,355 : INFO: common :yaml file: params.yaml loaded successfully]
[2024-03-10 15:23:18,355 : INFO: common :created directory at: artifacts]
[2024-03-10 15:23:18,356 : INFO: common :created directory at: artifacts/training]
[2024-03-10 15:23:18,842 : ERROR: main :[Errno 2] No such file or directory: 'artifacts/data_ingestion/kidney-images']
Traceback (most recent call last):
  File "main.py", line 31, in <module>
    obj.main()
  File "/home/sumedh/Documents/MLops_tutorial/Project_2/Kidney_disease_classification/src/cnn_classifier/pipeline/s3_model_training.py", line 21, in main
    raise e
  File "/home/sumedh/Documents/MLops_tutorial/Project_2/Kidney_disease_classification/src/cnn_classifier/pipeline/s3_model_training.py", line 17, in main
    training.train_valid_generator()
  File "/home/sumedh/Documents/MLops_tutorial/Project_2/Kidney_disease_classification/src/cnn_classifier/componants/model_training.py", line 37, in train_valid_generator
    self.valid_generator = valid_datagenerator.flow_from_directory(
  File "/home/sumedh/anaconda3/envs/classification/lib/python3.8/site-packages/keras/preprocessing/image.py", line 1648, in flow_from_directory
    return DirectoryIterator(
  File "/home/sumedh/anaconda3/envs/classification/lib/python3.8/site-packages/keras/preprocessing/image.py", line 563, in __init__
    for subdir in sorted(os.listdir(directory)):
FileNotFoundError: [Errno 2] No such file or directory: 'artifacts/data_ingestion/kidney-images'
[2024-03-10 15:23:56,938 : INFO: main :*******************]
[2024-03-10 15:23:56,938 : INFO: main :>>>>>> stage Training Phase started <<<<<<]
[2024-03-10 15:23:56,941 : INFO: common :yaml file: config/config.yaml loaded successfully]
[2024-03-10 15:23:56,942 : INFO: common :yaml file: params.yaml loaded successfully]
[2024-03-10 15:23:56,942 : INFO: common :created directory at: artifacts]
[2024-03-10 15:23:56,943 : INFO: common :created directory at: artifacts/training]
[2024-03-10 15:23:57,393 : ERROR: main :'Training' object has no attribute 'steps_per_epoch']
Traceback (most recent call last):
  File "main.py", line 31, in <module>
    obj.main()
  File "/home/sumedh/Documents/MLops_tutorial/Project_2/Kidney_disease_classification/src/cnn_classifier/pipeline/s3_model_training.py", line 21, in main
    raise e
  File "/home/sumedh/Documents/MLops_tutorial/Project_2/Kidney_disease_classification/src/cnn_classifier/pipeline/s3_model_training.py", line 18, in main
    training.train()
  File "/home/sumedh/Documents/MLops_tutorial/Project_2/Kidney_disease_classification/src/cnn_classifier/componants/model_training.py", line 76, in train
    steps_per_epochs = self.steps_per_epoch,
AttributeError: 'Training' object has no attribute 'steps_per_epoch'
[2024-03-10 15:24:23,896 : INFO: main :*******************]
[2024-03-10 15:24:23,896 : INFO: main :>>>>>> stage Training Phase started <<<<<<]
[2024-03-10 15:24:23,899 : INFO: common :yaml file: config/config.yaml loaded successfully]
[2024-03-10 15:24:23,900 : INFO: common :yaml file: params.yaml loaded successfully]
[2024-03-10 15:24:23,900 : INFO: common :created directory at: artifacts]
[2024-03-10 15:24:23,901 : INFO: common :created directory at: artifacts/training]
[2024-03-10 15:24:24,335 : ERROR: main :name 'callback_list' is not defined]
Traceback (most recent call last):
  File "main.py", line 31, in <module>
    obj.main()
  File "/home/sumedh/Documents/MLops_tutorial/Project_2/Kidney_disease_classification/src/cnn_classifier/pipeline/s3_model_training.py", line 21, in main
    raise e
  File "/home/sumedh/Documents/MLops_tutorial/Project_2/Kidney_disease_classification/src/cnn_classifier/pipeline/s3_model_training.py", line 18, in main
    training.train()
  File "/home/sumedh/Documents/MLops_tutorial/Project_2/Kidney_disease_classification/src/cnn_classifier/componants/model_training.py", line 79, in train
    callbacks  = callback_list
NameError: name 'callback_list' is not defined
[2024-03-10 15:24:37,676 : INFO: main :*******************]
[2024-03-10 15:24:37,676 : INFO: main :>>>>>> stage Training Phase started <<<<<<]
[2024-03-10 15:24:37,679 : INFO: common :yaml file: config/config.yaml loaded successfully]
[2024-03-10 15:24:37,680 : INFO: common :yaml file: params.yaml loaded successfully]
[2024-03-10 15:24:37,680 : INFO: common :created directory at: artifacts]
[2024-03-10 15:24:37,680 : INFO: common :created directory at: artifacts/training]
[2024-03-10 15:24:38,122 : ERROR: main :fit() got an unexpected keyword argument 'steps_per_epochs']
Traceback (most recent call last):
  File "main.py", line 31, in <module>
    obj.main()
  File "/home/sumedh/Documents/MLops_tutorial/Project_2/Kidney_disease_classification/src/cnn_classifier/pipeline/s3_model_training.py", line 21, in main
    raise e
  File "/home/sumedh/Documents/MLops_tutorial/Project_2/Kidney_disease_classification/src/cnn_classifier/pipeline/s3_model_training.py", line 18, in main
    training.train()
  File "/home/sumedh/Documents/MLops_tutorial/Project_2/Kidney_disease_classification/src/cnn_classifier/componants/model_training.py", line 73, in train
    self.model.fit(
  File "/home/sumedh/anaconda3/envs/classification/lib/python3.8/site-packages/keras/utils/traceback_utils.py", line 70, in error_handler
    raise e.with_traceback(filtered_tb) from None
  File "/home/sumedh/anaconda3/envs/classification/lib/python3.8/site-packages/keras/utils/traceback_utils.py", line 65, in error_handler
    return fn(*args, **kwargs)
TypeError: fit() got an unexpected keyword argument 'steps_per_epochs'
[2024-03-10 15:26:04,550 : INFO: main :*******************]
[2024-03-10 15:26:04,550 : INFO: main :>>>>>> stage Training Phase started <<<<<<]
[2024-03-10 15:26:04,553 : INFO: common :yaml file: config/config.yaml loaded successfully]
[2024-03-10 15:26:04,554 : INFO: common :yaml file: params.yaml loaded successfully]
[2024-03-10 15:26:04,555 : INFO: common :created directory at: artifacts]
[2024-03-10 15:26:04,555 : INFO: common :created directory at: artifacts/training]
[2024-03-10 15:26:48,577 : WARNING: data_adapter :Your input ran out of data; interrupting training. Make sure that your dataset or generator can generate at least `steps_per_epoch * epochs` batches (in this case, 12 batches). You may need to use the repeat() function when building your dataset.]
[2024-03-10 15:29:10,908 : ERROR: main :'Training' object has no attribute 'trained_model_path']
Traceback (most recent call last):
  File "main.py", line 31, in <module>
    obj.main()
  File "/home/sumedh/Documents/MLops_tutorial/Project_2/Kidney_disease_classification/src/cnn_classifier/pipeline/s3_model_training.py", line 21, in main
    raise e
  File "/home/sumedh/Documents/MLops_tutorial/Project_2/Kidney_disease_classification/src/cnn_classifier/pipeline/s3_model_training.py", line 18, in main
    training.train()
  File "/home/sumedh/Documents/MLops_tutorial/Project_2/Kidney_disease_classification/src/cnn_classifier/componants/model_training.py", line 84, in train
    path = self.trained_model_path,
AttributeError: 'Training' object has no attribute 'trained_model_path'
[2024-03-10 15:31:06,760 : INFO: main :*******************]
[2024-03-10 15:31:06,760 : INFO: main :>>>>>> stage Training Phase started <<<<<<]
[2024-03-10 15:31:06,762 : INFO: common :yaml file: config/config.yaml loaded successfully]
[2024-03-10 15:31:06,763 : INFO: common :yaml file: params.yaml loaded successfully]
[2024-03-10 15:31:06,763 : INFO: common :created directory at: artifacts]
[2024-03-10 15:31:06,764 : INFO: common :created directory at: artifacts/training]
[2024-03-10 15:31:44,740 : WARNING: data_adapter :Your input ran out of data; interrupting training. Make sure that your dataset or generator can generate at least `steps_per_epoch * epochs` batches (in this case, 12 batches). You may need to use the repeat() function when building your dataset.]
[2024-03-10 15:33:49,313 : INFO: main :>>>>>> stage Training Phase completed <<<<<<

x==========x]
[2024-03-14 14:12:20,147 : INFO: common :yaml file: config/config.yaml loaded successfully]
[2024-03-14 14:12:20,150 : INFO: common :yaml file: params.yaml loaded successfully]
[2024-03-14 14:12:20,150 : INFO: common :created directory at: artifacts]
[2024-03-14 14:12:20,150 : INFO: common :created directory at: artifacts/data_ingestion]
[2024-03-14 14:19:15,248 : INFO: main :Starting data ingestion pipeline]
[2024-03-14 14:20:48,231 : INFO: common :yaml file: config/config.yaml loaded successfully]
[2024-03-14 14:20:48,232 : INFO: common :yaml file: params.yaml loaded successfully]
[2024-03-14 14:20:48,233 : INFO: common :created directory at: artifacts]
[2024-03-14 14:20:48,233 : INFO: common :created directory at: artifacts/data_ingestion]
[2024-03-14 14:21:57,430 : INFO: main :*******************]
[2024-03-14 14:21:57,430 : INFO: main :>>>>>> stage Prepare base model started <<<<<<]
[2024-03-14 14:21:57,433 : INFO: common :yaml file: config/config.yaml loaded successfully]
[2024-03-14 14:21:57,434 : INFO: common :yaml file: params.yaml loaded successfully]
[2024-03-14 14:21:57,434 : INFO: common :created directory at: artifacts]
[2024-03-14 14:21:57,434 : INFO: common :created directory at: artifacts/prepare_base_model]
[2024-03-14 14:21:57,975 : WARNING: saving_utils :Compiled the loaded model, but the compiled metrics have yet to be built. `model.compile_metrics` will be empty until you train or evaluate the model.]
[2024-03-14 14:21:58,262 : INFO: main :>>>>>> stage Prepare base model completed <<<<<<

x==========x]
[2024-03-14 14:30:40,093 : INFO: main :*******************]
[2024-03-14 14:30:40,093 : INFO: main :>>>>>> stage Training Phase started <<<<<<]
[2024-03-14 14:30:40,096 : INFO: common :yaml file: config/config.yaml loaded successfully]
[2024-03-14 14:30:40,097 : INFO: common :yaml file: params.yaml loaded successfully]
[2024-03-14 14:30:40,098 : INFO: common :created directory at: artifacts]
[2024-03-14 14:30:40,098 : INFO: common :created directory at: artifacts/training]
[2024-03-14 14:31:18,011 : WARNING: data_adapter :Your input ran out of data; interrupting training. Make sure that your dataset or generator can generate at least `steps_per_epoch * epochs` batches (in this case, 12 batches). You may need to use the repeat() function when building your dataset.]
[2024-03-14 14:33:40,941 : INFO: main :>>>>>> stage Training Phase completed <<<<<<

x==========x]
[2024-03-18 15:56:25,592 : INFO: main :*******************]
[2024-03-18 15:56:25,602 : INFO: main :>>>>>> stage Evaluation started <<<<<<]
[2024-03-18 15:56:25,606 : INFO: common :yaml file: config/config.yaml loaded successfully]
[2024-03-18 15:56:25,607 : INFO: common :yaml file: params.yaml loaded successfully]
[2024-03-18 15:56:25,608 : INFO: common :created directory at: artifacts]
[2024-03-18 15:56:25,608 : ERROR: main :'Evaluation' object has no attribute 'load_model']
Traceback (most recent call last):
  File "main.py", line 43, in <module>
    obj.main()
  File "/home/sumedh/Documents/MLops_tutorial/Project_2/Kidney_disease_classification/src/cnn_classifier/pipeline/s4_evaluation.py", line 17, in main
    raise e
  File "/home/sumedh/Documents/MLops_tutorial/Project_2/Kidney_disease_classification/src/cnn_classifier/pipeline/s4_evaluation.py", line 14, in main
    evaluation.evaluation()
  File "/home/sumedh/Documents/MLops_tutorial/Project_2/Kidney_disease_classification/src/cnn_classifier/componants/evaluation.py", line 43, in evaluation
    self.model = self.load_model(self.config.path_of_model)
AttributeError: 'Evaluation' object has no attribute 'load_model'
[2024-03-18 15:57:05,477 : INFO: main :*******************]
[2024-03-18 15:57:05,477 : INFO: main :>>>>>> stage Evaluation started <<<<<<]
[2024-03-18 15:57:05,479 : INFO: common :yaml file: config/config.yaml loaded successfully]
[2024-03-18 15:57:05,481 : INFO: common :yaml file: params.yaml loaded successfully]
[2024-03-18 15:57:05,481 : INFO: common :created directory at: artifacts]
[2024-03-18 15:57:06,131 : ERROR: main :name 'model' is not defined]
Traceback (most recent call last):
  File "main.py", line 43, in <module>
    obj.main()
  File "/home/sumedh/Documents/MLops_tutorial/Project_2/Kidney_disease_classification/src/cnn_classifier/pipeline/s4_evaluation.py", line 17, in main
    raise e
  File "/home/sumedh/Documents/MLops_tutorial/Project_2/Kidney_disease_classification/src/cnn_classifier/pipeline/s4_evaluation.py", line 14, in main
    evaluation.evaluation()
  File "/home/sumedh/Documents/MLops_tutorial/Project_2/Kidney_disease_classification/src/cnn_classifier/componants/evaluation.py", line 45, in evaluation
    self.score = model.evaluate(self.valid_generator)
NameError: name 'model' is not defined
[2024-03-18 15:57:27,678 : INFO: main :*******************]
[2024-03-18 15:57:27,678 : INFO: main :>>>>>> stage Evaluation started <<<<<<]
[2024-03-18 15:57:27,680 : INFO: common :yaml file: config/config.yaml loaded successfully]
[2024-03-18 15:57:27,681 : INFO: common :yaml file: params.yaml loaded successfully]
[2024-03-18 15:57:27,681 : INFO: common :created directory at: artifacts]
[2024-03-18 15:57:42,011 : ERROR: main :local variable 'scores' referenced before assignment]
Traceback (most recent call last):
  File "main.py", line 43, in <module>
    obj.main()
  File "/home/sumedh/Documents/MLops_tutorial/Project_2/Kidney_disease_classification/src/cnn_classifier/pipeline/s4_evaluation.py", line 17, in main
    raise e
  File "/home/sumedh/Documents/MLops_tutorial/Project_2/Kidney_disease_classification/src/cnn_classifier/pipeline/s4_evaluation.py", line 14, in main
    evaluation.evaluation()
  File "/home/sumedh/Documents/MLops_tutorial/Project_2/Kidney_disease_classification/src/cnn_classifier/componants/evaluation.py", line 46, in evaluation
    self.save_score()
  File "/home/sumedh/Documents/MLops_tutorial/Project_2/Kidney_disease_classification/src/cnn_classifier/componants/evaluation.py", line 49, in save_score
    scores = {"Loss": scores[0], "Accuracy": scores[1]}
UnboundLocalError: local variable 'scores' referenced before assignment
[2024-03-18 15:58:22,632 : INFO: main :*******************]
[2024-03-18 15:58:22,632 : INFO: main :>>>>>> stage Evaluation started <<<<<<]
[2024-03-18 15:58:22,635 : INFO: common :yaml file: config/config.yaml loaded successfully]
[2024-03-18 15:58:22,636 : INFO: common :yaml file: params.yaml loaded successfully]
[2024-03-18 15:58:22,636 : INFO: common :created directory at: artifacts]
[2024-03-18 15:58:36,925 : ERROR: main :name 'scores' is not defined]
Traceback (most recent call last):
  File "main.py", line 43, in <module>
    obj.main()
  File "/home/sumedh/Documents/MLops_tutorial/Project_2/Kidney_disease_classification/src/cnn_classifier/pipeline/s4_evaluation.py", line 17, in main
    raise e
  File "/home/sumedh/Documents/MLops_tutorial/Project_2/Kidney_disease_classification/src/cnn_classifier/pipeline/s4_evaluation.py", line 14, in main
    evaluation.evaluation()
  File "/home/sumedh/Documents/MLops_tutorial/Project_2/Kidney_disease_classification/src/cnn_classifier/componants/evaluation.py", line 46, in evaluation
    self.save_score()
  File "/home/sumedh/Documents/MLops_tutorial/Project_2/Kidney_disease_classification/src/cnn_classifier/componants/evaluation.py", line 49, in save_score
    self.scores = {"Loss": scores[0], "Accuracy": scores[1]}
NameError: name 'scores' is not defined
[2024-03-18 15:59:51,621 : INFO: main :*******************]
[2024-03-18 15:59:51,621 : INFO: main :>>>>>> stage Evaluation started <<<<<<]
[2024-03-18 15:59:51,623 : INFO: common :yaml file: config/config.yaml loaded successfully]
[2024-03-18 15:59:51,624 : INFO: common :yaml file: params.yaml loaded successfully]
[2024-03-18 15:59:51,624 : INFO: common :created directory at: artifacts]
[2024-03-18 16:00:05,927 : INFO: common :json file saved at: scores.json]
[2024-03-18 16:00:05,927 : ERROR: main :module 'mlflow' has no attribute 'get_traking_uri']
Traceback (most recent call last):
  File "main.py", line 43, in <module>
    obj.main()
  File "/home/sumedh/Documents/MLops_tutorial/Project_2/Kidney_disease_classification/src/cnn_classifier/pipeline/s4_evaluation.py", line 17, in main
    raise e
  File "/home/sumedh/Documents/MLops_tutorial/Project_2/Kidney_disease_classification/src/cnn_classifier/pipeline/s4_evaluation.py", line 15, in main
    evaluation.log_mlflow()
  File "/home/sumedh/Documents/MLops_tutorial/Project_2/Kidney_disease_classification/src/cnn_classifier/componants/evaluation.py", line 54, in log_mlflow
    tracking_uri_type_store = urlparse(mlflow.get_traking_uri()).scheme
AttributeError: module 'mlflow' has no attribute 'get_traking_uri'
[2024-03-18 16:00:27,939 : INFO: main :*******************]
[2024-03-18 16:00:27,939 : INFO: main :>>>>>> stage Evaluation started <<<<<<]
[2024-03-18 16:00:27,941 : INFO: common :yaml file: config/config.yaml loaded successfully]
[2024-03-18 16:00:27,942 : INFO: common :yaml file: params.yaml loaded successfully]
[2024-03-18 16:00:27,943 : INFO: common :created directory at: artifacts]
[2024-03-18 16:00:42,498 : INFO: common :json file saved at: scores.json]
[2024-03-18 16:00:45,050 : ERROR: main :'Evaluation' object has no attribute 'scores']
Traceback (most recent call last):
  File "main.py", line 43, in <module>
    obj.main()
  File "/home/sumedh/Documents/MLops_tutorial/Project_2/Kidney_disease_classification/src/cnn_classifier/pipeline/s4_evaluation.py", line 17, in main
    raise e
  File "/home/sumedh/Documents/MLops_tutorial/Project_2/Kidney_disease_classification/src/cnn_classifier/pipeline/s4_evaluation.py", line 15, in main
    evaluation.log_mlflow()
  File "/home/sumedh/Documents/MLops_tutorial/Project_2/Kidney_disease_classification/src/cnn_classifier/componants/evaluation.py", line 59, in log_mlflow
    mlflow.log_metrics({"Loss": self.scores[0], "Accuracy": self.scores[1]})
AttributeError: 'Evaluation' object has no attribute 'scores'
[2024-03-18 16:01:09,369 : INFO: main :*******************]
[2024-03-18 16:01:09,369 : INFO: main :>>>>>> stage Evaluation started <<<<<<]
[2024-03-18 16:01:09,371 : INFO: common :yaml file: config/config.yaml loaded successfully]
[2024-03-18 16:01:09,372 : INFO: common :yaml file: params.yaml loaded successfully]
[2024-03-18 16:01:09,373 : INFO: common :created directory at: artifacts]
[2024-03-18 16:01:24,287 : INFO: common :json file saved at: scores.json]
[2024-03-18 16:01:27,749 : WARNING: save :Found untraced functions such as _jit_compiled_convolution_op, _jit_compiled_convolution_op, _jit_compiled_convolution_op, _jit_compiled_convolution_op, _jit_compiled_convolution_op while saving (showing 5 of 14). These functions will not be directly callable after loading.]
[2024-03-18 16:01:28,330 : INFO: builder_impl :Assets written to: /tmp/tmp6lxsmh53/model/data/model/assets]
[2024-03-18 16:02:12,943 : INFO: main :>>>>>> stage Evaluation completed <<<<<<

x==========x]
